Exception in user code:
------------------------------------------------------------
--- Logging error ---
Traceback (most recent call last):
  File "/home/wangzhaowei/anaconda3/envs/rongyf/lib/python3.6/logging/__init__.py", line 992, in emit
    msg = self.format(record)
  File "/home/wangzhaowei/anaconda3/envs/rongyf/lib/python3.6/logging/__init__.py", line 838, in format
    return fmt.format(record)
  File "/home/wangzhaowei/anaconda3/envs/rongyf/lib/python3.6/logging/__init__.py", line 575, in format
    record.message = record.getMessage()
  File "/home/wangzhaowei/anaconda3/envs/rongyf/lib/python3.6/logging/__init__.py", line 338, in getMessage
    msg = msg % self.args
TypeError: not all arguments converted during string formatting
Call stack:
  File "main.py", line 320, in <module>
    train_cnn_model('pnasnet5large_class3', gpu_ids, batch_size)
  File "main.py", line 276, in train_cnn_model
    logging.debug("Let's use ", len(gpu_ids), " GPUs!")
Message: "Let's use "
Arguments: (2, ' GPUs!')
Traceback (most recent call last):
  File "/home/wangzhaowei/anaconda3/envs/rongyf/lib/python3.6/site-packages/urllib3/connection.py", line 159, in _new_conn
    (self._dns_host, self.port), self.timeout, **extra_kw)
  File "/home/wangzhaowei/anaconda3/envs/rongyf/lib/python3.6/site-packages/urllib3/util/connection.py", line 80, in create_connection
    raise err
  File "/home/wangzhaowei/anaconda3/envs/rongyf/lib/python3.6/site-packages/urllib3/util/connection.py", line 70, in create_connection
    sock.connect(sa)
ConnectionRefusedError: [Errno 111] Connection refused

During handling of the above exception, another exception occurred:

Traceback (most recent call last):
  File "/home/wangzhaowei/anaconda3/envs/rongyf/lib/python3.6/site-packages/urllib3/connectionpool.py", line 600, in urlopen
    chunked=chunked)
  File "/home/wangzhaowei/anaconda3/envs/rongyf/lib/python3.6/site-packages/urllib3/connectionpool.py", line 354, in _make_request
    conn.request(method, url, **httplib_request_kw)
  File "/home/wangzhaowei/anaconda3/envs/rongyf/lib/python3.6/http/client.py", line 1239, in request
    self._send_request(method, url, body, headers, encode_chunked)
  File "/home/wangzhaowei/anaconda3/envs/rongyf/lib/python3.6/http/client.py", line 1285, in _send_request
    self.endheaders(body, encode_chunked=encode_chunked)
  File "/home/wangzhaowei/anaconda3/envs/rongyf/lib/python3.6/http/client.py", line 1234, in endheaders
    self._send_output(message_body, encode_chunked=encode_chunked)
  File "/home/wangzhaowei/anaconda3/envs/rongyf/lib/python3.6/http/client.py", line 1026, in _send_output
    self.send(msg)
  File "/home/wangzhaowei/anaconda3/envs/rongyf/lib/python3.6/http/client.py", line 964, in send
    self.connect()
  File "/home/wangzhaowei/anaconda3/envs/rongyf/lib/python3.6/site-packages/urllib3/connection.py", line 181, in connect
    conn = self._new_conn()
  File "/home/wangzhaowei/anaconda3/envs/rongyf/lib/python3.6/site-packages/urllib3/connection.py", line 168, in _new_conn
    self, "Failed to establish a new connection: %s" % e)
urllib3.exceptions.NewConnectionError: <urllib3.connection.HTTPConnection object at 0x7fe2de488b00>: Failed to establish a new connection: [Errno 111] Connection refused

During handling of the above exception, another exception occurred:

Traceback (most recent call last):
  File "/home/wangzhaowei/anaconda3/envs/rongyf/lib/python3.6/site-packages/requests/adapters.py", line 449, in send
    timeout=timeout
  File "/home/wangzhaowei/anaconda3/envs/rongyf/lib/python3.6/site-packages/urllib3/connectionpool.py", line 638, in urlopen
    _stacktrace=sys.exc_info()[2])
  File "/home/wangzhaowei/anaconda3/envs/rongyf/lib/python3.6/site-packages/urllib3/util/retry.py", line 399, in increment
    raise MaxRetryError(_pool, url, error or ResponseError(cause))
urllib3.exceptions.MaxRetryError: HTTPConnectionPool(host='localhost', port=8097): Max retries exceeded with url: /env/train_loss (Caused by NewConnectionError('<urllib3.connection.HTTPConnection object at 0x7fe2de488b00>: Failed to establish a new connection: [Errno 111] Connection refused',))

During handling of the above exception, another exception occurred:

Traceback (most recent call last):
  File "/home/wangzhaowei/anaconda3/envs/rongyf/lib/python3.6/site-packages/visdom/__init__.py", line 548, in _send
    data=json.dumps(msg),
  File "/home/wangzhaowei/anaconda3/envs/rongyf/lib/python3.6/site-packages/requests/sessions.py", line 581, in post
    return self.request('POST', url, data=data, json=json, **kwargs)
  File "/home/wangzhaowei/anaconda3/envs/rongyf/lib/python3.6/site-packages/requests/sessions.py", line 533, in request
    resp = self.send(prep, **send_kwargs)
  File "/home/wangzhaowei/anaconda3/envs/rongyf/lib/python3.6/site-packages/requests/sessions.py", line 646, in send
    r = adapter.send(request, **kwargs)
  File "/home/wangzhaowei/anaconda3/envs/rongyf/lib/python3.6/site-packages/requests/adapters.py", line 516, in send
    raise ConnectionError(e, request=request)
requests.exceptions.ConnectionError: HTTPConnectionPool(host='localhost', port=8097): Max retries exceeded with url: /env/train_loss (Caused by NewConnectionError('<urllib3.connection.HTTPConnection object at 0x7fe2de488b00>: Failed to establish a new connection: [Errno 111] Connection refused',))
